<?xml version="1.0" ?>
<!-- =================================================================================== -->
<!-- |    This document was autogenerated by xacro from airsbot2.urdf.xacro            | -->
<!-- |    EDITING THIS FILE BY HAND IS NOT RECOMMENDED                                 | -->
<!-- =================================================================================== -->
<robot name="airsbot2">
  <material name="black">
    <color rgba="0.0 0.0 0.0 1.0"/>
  </material>
  <material name="dark">
    <color rgba="0.3 0.3 0.3 1.0"/>
  </material>
  <material name="light_black">
    <color rgba="0.4 0.4 0.4 1.0"/>
  </material>
  <material name="blue">
    <color rgba="0.0 0.0 0.8 1.0"/>
  </material>
  <material name="green">
    <color rgba="0.0 0.8 0.0 1.0"/>
  </material>
  <material name="grey">
    <color rgba="0.5 0.5 0.5 1.0"/>
  </material>
  <material name="orange">
    <color rgba="1.0 0.4235 0.0392 1.0"/>
  </material>
  <material name="brown">
    <color rgba="0.8706 0.8118 0.7647 1.0"/>
  </material>
  <material name="red">
    <color rgba="0.8 0.0 0.0 1.0"/>
  </material>
  <material name="white">
    <color rgba="1.0 1.0 1.0 1.0"/>
  </material>
  <material name="zed2_mat">
    <color rgba="0.25 0.25 0.25 1.0"/>
  </material>
  <material name="zed2i_mat">
    <color rgba="0.25 0.25 0.25 1.0"/>
  </material>
  <material name="virtual_mat">
    <color rgba="0.25 0.25 0.25 1.0"/>
  </material>
  <material name="aluminum">
    <color rgba="0.5 0.5 0.5 1"/>
  </material>
  <material name="silver">
    <color rgba="0.8 0.8 0.8 1.0"/>
  </material>
  <material name="tire">
    <color rgba="0.1 0.1 0.1 1.0"/>
  </material>
  <link name="base_footprint"/>
  <joint name="base_joint" type="fixed">
    <parent link="base_footprint"/>
    <child link="base_link"/>
    <origin rpy="0.0 0.0 0.0" xyz="0.0 0.0 0.309"/>
  </joint>
  <link name="base_link">
    <visual>
      <origin rpy="0.0 0.0 0.0" xyz="0.0 0.0 -0.03"/>
      <geometry>
        <box size="0.7 0.588 0.056"/>
      </geometry>
      <material name="grey"/>
    </visual>
    <collision>
      <origin rpy="0.0 0.0 0.0" xyz="0.0 0.0 -0.03"/>
      <geometry>
        <box size="0.7 0.588 0.056"/>
      </geometry>
    </collision>
    <inertial>
      <origin rpy="0.0 0.0 0.0" xyz="0.0 0.0 -0.030"/>
      <mass value="30.0"/>
      <inertia ixx="7.8" ixy="0.0" ixz="0.0" iyy="7.8" iyz="0.0" izz="7.8"/>
    </inertial>
  </link>
  <joint name="left_front_driven_wheel_joint" type="continuous">
    <parent link="base_link"/>
    <child link="left_front_driven_wheel_link"/>
    <origin rpy="-1.5707963267948966 0.0 0.0" xyz="0.23 0.219 -0.182"/>
    <axis xyz="0.0 0.0 1.0"/>
    <limit effort="25.0" lower="-1e+16" upper="1e+16" velocity="75.36"/>
    <joint_properties damping="30.0" friction="110.0"/>
  </joint>
  <link name="left_front_driven_wheel_link">
    <visual>
      <origin rpy="0.0 0.0 0.0" xyz="0.0 0.0 0.0"/>
      <geometry>
        <mesh filename="package://airship_description/urdf/meshes/wheel.stl" scale="0.001 0.001 0.001"/>
      </geometry>
      <material name="tire"/>
    </visual>
    <collision>
      <origin rpy="0.0 0.0 0.0" xyz="0.0 0.0 0.0"/>
      <geometry>
        <cylinder length="0.075" radius="0.120"/>
      </geometry>
    </collision>
    <inertial>
      <origin xyz="0.0 0.0 0.0"/>
      <mass value="7.15"/>
      <inertia ixx="0.11042056" ixy="0.0" ixz="0.0" iyy="0.11042056" iyz="0.0" izz="0.11042056"/>
    </inertial>
  </link>
  <joint name="left_back_driven_wheel_joint" type="continuous">
    <parent link="base_link"/>
    <child link="left_back_driven_wheel_link"/>
    <origin rpy="-1.5707963267948966 0.0 0.0" xyz="-0.23 0.219 -0.182"/>
    <axis xyz="0.0 0.0 1.0"/>
    <limit effort="25.0" lower="-1e+16" upper="1e+16" velocity="75.36"/>
    <joint_properties damping="30.0" friction="110.0"/>
  </joint>
  <link name="left_back_driven_wheel_link">
    <visual>
      <origin rpy="0.0 0.0 0.0" xyz="0.0 0.0 0.0"/>
      <geometry>
        <mesh filename="package://airship_description/urdf/meshes/wheel.stl" scale="0.001 0.001 0.001"/>
      </geometry>
      <material name="tire"/>
    </visual>
    <collision>
      <origin rpy="0.0 0.0 0.0" xyz="0.0 0.0 0.0"/>
      <geometry>
        <cylinder length="0.075" radius="0.120"/>
      </geometry>
    </collision>
    <inertial>
      <origin xyz="0.0 0.0 0.0"/>
      <mass value="7.15"/>
      <inertia ixx="0.11042056" ixy="0.0" ixz="0.0" iyy="0.11042056" iyz="0.0" izz="0.11042056"/>
    </inertial>
  </link>
  <joint name="right_front_driven_wheel_joint" type="continuous">
    <parent link="base_link"/>
    <child link="right_front_driven_wheel_link"/>
    <origin rpy="-1.5707963267948966 0.0 0.0" xyz="0.23 -0.219 -0.182"/>
    <axis xyz="0.0 0.0 1.0"/>
    <limit effort="25.0" lower="-1e+16" upper="1e+16" velocity="75.36"/>
    <joint_properties damping="30.0" friction="110.0"/>
  </joint>
  <link name="right_front_driven_wheel_link">
    <visual>
      <origin rpy="0.0 3.141592653589793 0.0" xyz="0.0 0.0 0.0"/>
      <geometry>
        <mesh filename="package://airship_description/urdf/meshes/wheel.stl" scale="0.001 0.001 0.001"/>
      </geometry>
      <material name="tire"/>
    </visual>
    <collision>
      <origin rpy="0.0 0.0 0.0" xyz="0.0 0.0 0.0"/>
      <geometry>
        <cylinder length="0.075" radius="0.120"/>
      </geometry>
    </collision>
    <inertial>
      <origin xyz="0.0 0.0 0.0"/>
      <mass value="7.15"/>
      <inertia ixx="0.11042056" ixy="0.0" ixz="0.0" iyy="0.11042056" iyz="0.0" izz="0.11042056"/>
    </inertial>
  </link>
  <joint name="right_back_driven_wheel_joint" type="continuous">
    <parent link="base_link"/>
    <child link="right_back_driven_wheel_link"/>
    <origin rpy="-1.5707963267948966 0.0 0.0" xyz="-0.23 -0.219 -0.182"/>
    <axis xyz="0.0 0.0 1.0"/>
    <limit effort="25.0" lower="-1e+16" upper="1e+16" velocity="75.36"/>
    <joint_properties damping="30.0" friction="110.0"/>
  </joint>
  <link name="right_back_driven_wheel_link">
    <visual>
      <origin rpy="0.0 3.141592653589793 0.0" xyz="0.0 0.0 0.0"/>
      <geometry>
        <mesh filename="package://airship_description/urdf/meshes/wheel.stl" scale="0.001 0.001 0.001"/>
      </geometry>
      <material name="tire"/>
    </visual>
    <collision>
      <origin rpy="0.0 0.0 0.0" xyz="0.0 0.0 0.0"/>
      <geometry>
        <cylinder length="0.075" radius="0.120"/>
      </geometry>
    </collision>
    <inertial>
      <origin xyz="0.0 0.0 0.0"/>
      <mass value="7.15"/>
      <inertia ixx="0.11042056" ixy="0.0" ixz="0.0" iyy="0.11042056" iyz="0.0" izz="0.11042056"/>
    </inertial>
  </link>
  <joint name="right_driving_wheel_joint" type="continuous">
    <parent link="base_link"/>
    <child link="right_driving_wheel_link"/>
    <origin rpy="-1.5707963267948966 0.0 0.0" xyz="0.0 -0.219 -0.182"/>
    <axis xyz="0.0 0.0 1.0"/>
    <limit effort="25.0" lower="-1e+16" upper="1e+16" velocity="75.36"/>
    <joint_properties damping="30.0" friction="110.0"/>
  </joint>
  <link name="right_driving_wheel_link">
    <collision>
      <origin rpy="0.0 0.0 0.0" xyz="0.0 0.0 0.0"/>
      <geometry>
        <cylinder length="0.075" radius="0.1205"/>
      </geometry>
    </collision>
    <inertial>
      <origin xyz="0.0 0.0 0.0"/>
      <mass value="7.15"/>
      <inertia ixx="0.11042056" ixy="0.0" ixz="0.0" iyy="0.11042056" iyz="0.0" izz="0.11042056"/>
    </inertial>
  </link>
  <joint name="left_driving_wheel_joint" type="continuous">
    <parent link="base_link"/>
    <child link="left_driving_wheel_link"/>
    <origin rpy="-1.5707963267948966 0.0 0.0" xyz="0.0 0.219 -0.182"/>
    <axis xyz="0.0 0.0 1.0"/>
    <limit effort="25.0" lower="-1e+16" upper="1e+16" velocity="75.36"/>
    <joint_properties damping="30.0" friction="110.0"/>
  </joint>
  <link name="left_driving_wheel_link">
    <collision>
      <origin rpy="0.0 0.0 0.0" xyz="0.0 0.0 0.0"/>
      <geometry>
        <cylinder length="0.075" radius="0.1205"/>
      </geometry>
    </collision>
    <inertial>
      <origin xyz="0.0 0.0 0.0"/>
      <mass value="7.15"/>
      <inertia ixx="0.11042056" ixy="0.0" ixz="0.0" iyy="0.11042056" iyz="0.0" izz="0.11042056"/>
    </inertial>
  </link>
  <joint name="imu_joint" type="fixed">
    <parent link="base_link"/>
    <child link="imu_link"/>
    <origin rpy="0.0 0.0 0.0" xyz="0.255 0.0 0.033"/>
  </joint>
  <link name="imu_link"/>
  <joint name="lidar_joint" type="fixed">
    <parent link="base_link"/>
    <child link="lidar_link"/>
    <origin rpy="0.0 0.0 0.0" xyz="0.255 0.0 0.156"/>
  </joint>
  <link name="lidar_link">
    <visual>
      <origin rpy="0.0 0.0 0.0" xyz="0.0 0.0 0.0"/>
      <geometry>
        <mesh filename="package://airship_description/urdf/meshes/Helios_Lede_20220314.stl" scale="0.001 0.001 0.001"/>
      </geometry>
      <material name="white"/>
    </visual>
    <collision>
      <origin rpy="0.0 0.0 0.0" xyz="0.0 0.0 0.0"/>
      <geometry>
        <mesh filename="package://airship_description/urdf/meshes/Helios_Lede_20220314.stl" scale="0.001 0.001 0.001"/>
      </geometry>
    </collision>
    <inertial>
      <origin xyz="0.0 0.0 0.0"/>
      <mass value="0.5"/>
      <inertia ixx="0.11042056" ixy="0.0" ixz="0.0" iyy="0.11042056" iyz="0.0" izz="0.11042056"/>
    </inertial>
  </link>
  <joint name="lidar_optical_joint" type="fixed">
    <parent link="lidar_link"/>
    <child link="rslidar"/>
    <origin rpy="0.0 0.0 0.0" xyz="0.0 0.0 0.0"/>
  </joint>
  <link name="rslidar"/>
  <link name="front_camera_link"/>
  <joint name="zed_camera_joint" type="fixed">
    <parent link="base_link"/>
    <child link="front_camera_link"/>
    <origin rpy="0.0 0.0 0.0" xyz="0.320 0.0 0.203"/>
  </joint>
  <joint name="zed2_camera_joint" type="fixed">
    <origin rpy="0 0 0" xyz="0 0 0"/>
    <parent link="front_camera_link"/>
    <child link="zed2_camera_link"/>
  </joint>
  <!-- Camera mounting point (the threaded screw hole in the bottom) -->
  <link name="zed2_camera_link">
    <visual>
      <origin rpy="0 0 0" xyz="0 0 0"/>
      <geometry>
        <mesh filename="package://airship_description/urdf/meshes/ZED2.stl" scale="0.001 0.001 0.001"/>
      </geometry>
      <material name="zed2_mat"/>
    </visual>
    <inertial>
      <mass value="0.0564"/>
      <origin xyz="0 0 0"/>
      <inertia ixx="0.003881243" ixy="0.0" ixz="0.0" iyy="0.000498940" iyz="0.0" izz="0.003879257"/>
    </inertial>
  </link>
  <!-- Camera Center -->
  <link name="zed2_camera_center">
    </link>
  <joint name="zed2_camera_center_joint" type="fixed">
    <parent link="zed2_camera_link"/>
    <child link="zed2_camera_center"/>
    <origin rpy="0 0.05 0" xyz="0 0 0.015"/>
  </joint>
  <!-- Left Camera -->
  <link name="zed2_left_camera_frame">
    </link>
  <joint name="zed2_left_camera_joint" type="fixed">
    <parent link="zed2_camera_center"/>
    <child link="zed2_left_camera_frame"/>
    <origin rpy="0 0 0" xyz="-0.01 0.06 0"/>
  </joint>
  <link name="zed2_left_camera_optical_frame"/>
  <joint name="zed2_left_camera_optical_joint" type="fixed">
    <origin rpy="-1.5707963267948966 0.0 -1.5707963267948966" xyz="0 0 0"/>
    <parent link="zed2_left_camera_frame"/>
    <child link="zed2_left_camera_optical_frame"/>
  </joint>
  <!-- Right Camera -->
  <link name="zed2_right_camera_frame">
    </link>
  <joint name="zed2_right_camera_joint" type="fixed">
    <parent link="zed2_camera_center"/>
    <child link="zed2_right_camera_frame"/>
    <origin rpy="0 0 0" xyz="-0.01 -0.06 0"/>
  </joint>
  <link name="zed2_right_camera_optical_frame"/>
  <joint name="zed2_right_camera_optical_joint" type="fixed">
    <origin rpy="-1.5707963267948966 0.0 -1.5707963267948966" xyz="0 0 0"/>
    <parent link="zed2_right_camera_frame"/>
    <child link="zed2_right_camera_optical_frame"/>
  </joint>
  <link name="zed2_mag_link"/>
  <joint name="zed2_mag_joint" type="fixed">
    <parent link="zed2_camera_center"/>
    <child link="zed2_mag_link"/>
    <origin rpy="0 0 0" xyz="0 0 0"/>
  </joint>
  <link name="zed2_baro_link"/>
  <joint name="zed2_baro_joint" type="fixed">
    <parent link="zed2_camera_center"/>
    <child link="zed2_baro_link"/>
    <origin rpy="0 0 0" xyz="0 0 0"/>
  </joint>
  <link name="zed2_temp_left_link"/>
  <joint name="zed2_temp_left_joint" type="fixed">
    <parent link="zed2_left_camera_frame"/>
    <child link="zed2_temp_left_link"/>
    <origin rpy="0 0 0" xyz="0 0 0"/>
  </joint>
  <link name="zed2_temp_right_link"/>
  <joint name="zed2_temp_right_joint" type="fixed">
    <parent link="zed2_right_camera_frame"/>
    <child link="zed2_temp_right_link"/>
    <origin rpy="0 0 0" xyz="0 0 0"/>
  </joint>
  <joint name="carrier_joint" type="fixed">
    <parent link="base_link"/>
    <child link="carrier_link"/>
    <origin rpy="0.0 0.0 0.0" xyz="0.255 0.0 0.033"/>
  </joint>
  <link name="carrier_link">
    <visual>
      <origin rpy="0.0 0.0 0.0" xyz="0.0 0.0 0.0"/>
      <geometry>
        <mesh filename="package://airship_description/urdf/meshes/carrier.stl" scale="0.001 0.001 0.001"/>
      </geometry>
      <material name="silver"/>
    </visual>
    <collision>
      <origin rpy="0.0 0.0 0.0" xyz="0.0 0.0 0.0"/>
      <geometry>
        <mesh filename="package://airship_description/urdf/meshes/carrier.stl" scale="0.001 0.001 0.001"/>
      </geometry>
    </collision>
    <inertial>
      <origin xyz="0.0 0.0 0.0"/>
      <mass value="0.1"/>
      <inertia ixx="0.11042056" ixy="0.0" ixz="0.0" iyy="0.11042056" iyz="0.0" izz="0.11042056"/>
    </inertial>
  </link>
  <joint name="manipulator_base_joint" type="fixed">
    <parent link="base_link"/>
    <child link="manipulator_base_link"/>
    <origin rpy="0.0 0.0 0.0" xyz="0.255 0.0 0.262"/>
  </joint>
  <link name="manipulator_base_link">
    <visual>
      <origin rpy="0.0 0.0 0.0" xyz="0.0 0.0 0.0"/>
      <geometry>
        <mesh filename="package://airship_description/urdf/meshes/manipulator_base.stl" scale="0.001 0.001 0.001"/>
      </geometry>
      <material name="grey"/>
    </visual>
    <collision>
      <origin rpy="0.0 0.0 0.0" xyz="0.0 0.0 0.0"/>
      <geometry>
        <mesh filename="package://airship_description/urdf/meshes/manipulator_base.stl" scale="0.001 0.001 0.001"/>
      </geometry>
    </collision>
    <inertial>
      <origin xyz="0.0 0.0 0.0"/>
      <mass value="0.1"/>
      <inertia ixx="0.11042056" ixy="0.0" ixz="0.0" iyy="0.11042056" iyz="0.0" izz="0.11042056"/>
    </inertial>
  </link>
  <link name="base">
    <visual>
      <geometry>
        <mesh filename="package://airship_description/urdf/meshes//arm_base.stl" scale="0.001 0.001 0.001"/>
      </geometry>
      <origin rpy="1.5707963267948966 0.0 0.0" xyz="0.0 0.0 0.0"/>
      <material name="white"/>
    </visual>
    <collision>
      <geometry>
        <mesh filename="package://airship_description/urdf/meshes//arm_base.stl" scale="0.001 0.001 0.001"/>
      </geometry>
      <origin rpy="1.5707963267948966 0.0 0.0" xyz="0.0 0.0 0.0"/>
    </collision>
    <inertial>
      <origin rpy="0.0 0.0 0.0" xyz="0.0 0.0 0.050"/>
      <mass value="0.01"/>
      <inertia ixx="7.8" ixy="0.0" ixz="0.0" iyy="7.8" iyz="0.0" izz="7.8"/>
    </inertial>
  </link>
  <joint name="joint_base_to_manipulator_base_link" type="fixed">
    <parent link="manipulator_base_link"/>
    <child link="base"/>
    <origin rpy="0.0 0.0 0.0" xyz="0.0 0.0 0.0"/>
  </joint>
  <!-- Link 1 -->
  <link name="link1">
    <visual>
      <geometry>
        <mesh filename="package://airship_description/urdf/meshes//link1.stl" scale="0.001 0.001 0.001"/>
      </geometry>
      <origin rpy="0.0 0.0 3.141592653589793" xyz="0.0 0.0 -0.06"/>
      <material name="white"/>
    </visual>
    <collision>
      <geometry>
        <mesh filename="package://airship_description/urdf/meshes//link1.stl" scale="0.001 0.001 0.001"/>
      </geometry>
      <origin rpy="0.0 0.0 3.141592653589793" xyz="0.0 0.0 -0.06"/>
    </collision>
    <inertial>
      <origin rpy="0.0 0.0 0.0" xyz="0.0 0.0 -0.115"/>
      <mass value="0.01"/>
      <inertia ixx="7.8" ixy="0.0" ixz="0.0" iyy="7.8" iyz="0.0" izz="7.8"/>
    </inertial>
  </link>
  <joint name="joint_link1_to_base" type="revolute">
    <axis xyz="0.0 0.0 1.0"/>
    <parent link="base"/>
    <child link="link1"/>
    <origin rpy="0.0 0.0 0.0" xyz="0.0 0.0 0.22934"/>
    <dynamics damping="52.0"/>
    <limit effort="1000.0" lower="-3.141592653589793" upper="3.141592653589793" velocity="0"/>
  </joint>
  <!-- Link 2 -->
  <link name="link2">
    <visual>
      <geometry>
        <mesh filename="package://airship_description/urdf/meshes//link2.stl" scale="0.001 0.001 0.001"/>
      </geometry>
      <origin rpy="0.0 -1.5707963267948966 -1.5707963267948966" xyz="0.0 0.0 -0.0446"/>
      <material name="white"/>
    </visual>
    <collision>
      <geometry>
        <mesh filename="package://airship_description/urdf/meshes//link2.stl" scale="0.001 0.001 0.001"/>
      </geometry>
      <origin rpy="0.0 -1.5707963267948966 -1.5707963267948966" xyz="0.0 0.0 -0.0446"/>
    </collision>
    <inertial>
      <origin rpy="0.0 0.0 0.0" xyz="0.0 0.0 0.0"/>
      <mass value="0.01"/>
      <inertia ixx="7.8" ixy="0.0" ixz="0.0" iyy="7.8" iyz="0.0" izz="7.8"/>
    </inertial>
  </link>
  <joint name="joint_link2_to_link1" type="revolute">
    <axis xyz="0.0 0.0 -1.0"/>
    <parent link="link1"/>
    <child link="link2"/>
    <origin rpy="1.5707963267948966 0.0 0.0" xyz="0.0 0.0 0.0"/>
    <dynamics damping="52.0"/>
    <limit effort="1000.0" lower="-4.71238898038469" upper="1.5707963267948966" velocity="0.0"/>
  </joint>
  <!-- Link 3 -->
  <link name="link3">
    <visual>
      <geometry>
        <mesh filename="package://airship_description/urdf/meshes//link3.stl" scale="0.001 0.001 0.001"/>
      </geometry>
      <origin rpy="0 1.5707963267948966 -1.5707963267948966" xyz="0.0 0.0 -0.0444"/>
      <material name="white"/>
    </visual>
    <collision>
      <geometry>
        <mesh filename="package://airship_description/urdf/meshes//link3.stl" scale="0.001 0.001 0.001"/>
      </geometry>
      <origin rpy="0.0 1.5707963267948966 -1.5707963267948966" xyz="0.0 0.0 -0.0444"/>
    </collision>
    <inertial>
      <origin rpy="0.0 0.0 0.0" xyz="-0.135 0 -0.08"/>
      <mass value="0.01"/>
      <inertia ixx="7.8" ixy="0.0" ixz="0" iyy="7.8" iyz="0.0" izz="7.8"/>
    </inertial>
  </link>
  <joint name="joint_link3_to_link2" type="revolute">
    <axis xyz="0.0 0.0 -1.0"/>
    <parent link="link2"/>
    <child link="link3"/>
    <origin rpy="0.0 0.0 0.0" xyz="0.27 0.0 0.0"/>
    <dynamics damping="52.0"/>
    <limit effort="1000.0" lower="-2.607521902479528" upper="2.607521902479528" velocity="0.0"/>
  </joint>
  <!-- Link 4 -->
  <link name="link4">
    <visual>
      <geometry>
        <mesh filename="package://airship_description/urdf/meshes//link4.stl" scale="0.001 0.001 0.001"/>
      </geometry>
      <origin rpy="-1.5707963267948966 0.0 1.5707963267948966" xyz="0.0 0.0 0.041"/>
      <material name="white"/>
    </visual>
    <collision>
      <geometry>
        <mesh filename="package://airship_description/urdf/meshes//link4.stl" scale="0.001 0.001 0.001"/>
      </geometry>
      <origin rpy="-1.5707963267948966 0.0 1.5707963267948966" xyz="0.0 0.0 0.041"/>
    </collision>
    <inertial>
      <origin rpy="0.0 0.0 0.0" xyz="-0.134 0 0.09"/>
      <mass value="0.01"/>
      <inertia ixx="7.8" ixy="0.0" ixz="0" iyy="7.8" iyz="0.0" izz="7.8"/>
    </inertial>
  </link>
  <joint name="joint_link4_to_link3" type="revolute">
    <axis xyz="0.0 0.0 -1.0"/>
    <parent link="link3"/>
    <child link="link4"/>
    <origin rpy="0.0 0.0 0.0" xyz="0.267 0.0 -0.0745"/>
    <dynamics damping="52.0"/>
    <limit effort="1000.0" lower="-4.523893421169302" upper="1.382300767579509" velocity="0.0"/>
  </joint>
  <!-- Link 5 -->
  <link name="link5">
    <visual>
      <geometry>
        <mesh filename="package://airship_description/urdf/meshes//link5.stl" scale="0.001 0.001 0.001"/>
      </geometry>
      <origin rpy="0.0 -1.5707963267948966 3.141592653589793" xyz="-0.043 0.0 0.0"/>
      <material name="white"/>
    </visual>
    <collision>
      <geometry>
        <mesh filename="package://airship_description/urdf/meshes//link5.stl" scale="0.001 0.001 0.001"/>
      </geometry>
      <origin rpy="0 -1.5707963267948966 3.141592653589793" xyz="-0.043 0.0 0.0"/>
    </collision>
    <inertial>
      <origin rpy="0.0 0.0 0.0" xyz="0.0 0.0 0.0"/>
      <mass value="0.01"/>
      <inertia ixx="7.8" ixy="0.0" ixz="0" iyy="7.8" iyz="0.0" izz="7.8"/>
    </inertial>
  </link>
  <joint name="joint_link5_to_link4" type="revolute">
    <axis xyz="0.0 0.0 1.0"/>
    <parent link="link4"/>
    <child link="link5"/>
    <origin rpy="1.5707963267948966 -1.5707963267948966 0.0" xyz="0.0 -0.095 0.002"/>
    <dynamics damping="52.0"/>
    <limit effort="1000.0" lower="-2.921681167838508" upper="2.921681167838508" velocity="0.0"/>
  </joint>
  <!-- Link 6 -->
  <link name="link6">
    <visual>
      <geometry>
        <mesh filename="package://airship_description/urdf/meshes//link6.stl" scale="0.001 0.001 0.001"/>
      </geometry>
      <origin rpy="0.0 1.5707963267948966 0.0" xyz="0.01 0.0 0.0"/>
      <material name="silver"/>
    </visual>
    <collision>
      <geometry>
        <mesh filename="package://airship_description/urdf/meshes//link6.stl" scale="0.001 0.001 0.001"/>
      </geometry>
      <origin rpy="0.0 1.5707963267948966 0.0" xyz="0.01 0.0 0.0"/>
    </collision>
    <inertial>
      <origin rpy="0.0 0.0 0.0" xyz="0.0 0.0 0.0"/>
      <mass value="0.01"/>
      <inertia ixx="7.8" ixy="0.0" ixz="0" iyy="7.8" iyz="0.0" izz="7.8"/>
    </inertial>
  </link>
  <joint name="joint_link6_to_link5" type="revolute">
    <axis xyz="-1.0 0.0 0.0"/>
    <parent link="link5"/>
    <child link="link6"/>
    <origin rpy="-1.5707963267948966 0.0 0.0" xyz="-0.054 0.0 0.0"/>
    <dynamics damping="52.0"/>
    <limit effort="1000.0" lower="-3.015928947446201" upper="3.015928947446201" velocity="0"/>
  </joint>
  <!-- ee Link -->
  <link name="ee_link"/>
  <joint name="joint_ee_link_to_link6" type="fixed">
    <parent link="link6"/>
    <child link="ee_link"/>
    <origin rpy="2.748893571891069 0 3.141592653589793" xyz="0.0 0.0 0.0"/>
  </joint>
  <joint name="gripper_joint" type="fixed">
    <parent link="ee_link"/>
    <child link="camera_support_link"/>
    <origin rpy="0.0 0.0 0.0" xyz="0.0 0.0 0.0"/>
  </joint>
  <link name="camera_support_link">
    <visual>
      <geometry>
        <mesh filename="package://airship_description/urdf/meshes/camera_base.stl" scale="0.001 0.001 0.001"/>
      </geometry>
      <origin rpy="0.0 0.0 0.0" xyz="0.0 0.0 0.0"/>
      <material name="grey"/>
    </visual>
    <collision>
      <geometry>
        <mesh filename="package://airship_description/urdf/meshes/camera_base.stl" scale="0.001 0.001 0.001"/>
      </geometry>
      <origin rpy="0.0 0.0 0.0" xyz="0.0 0.0 0.0"/>
    </collision>
    <inertial>
      <origin rpy="0.0 0.0 0.0" xyz="0.0 0.0 0.0"/>
      <mass value="0.05"/>
      <inertia ixx="7.8" ixy="0.0" ixz="0.0" iyy="7.8" iyz="0.0" izz="7.8"/>
    </inertial>
  </link>
  <link name="gripper_base">
    <visual>
      <geometry>
        <mesh filename="package://airship_description/urdf/meshes/gripper_base.stl" scale="0.001 0.001 0.001"/>
      </geometry>
      <origin rpy="0.0 0.0 1.5707963267948966" xyz="-0.02 0.012 -0.018"/>
      <material name="white"/>
    </visual>
    <collision>
      <geometry>
        <mesh filename="package://airship_description/urdf/meshes/gripper_base.stl" scale="0.001 0.001 0.001"/>
      </geometry>
      <origin rpy="0.0 0.0 1.5707963267948966" xyz="-0.02 0.012 -0.018"/>
    </collision>
    <inertial>
      <origin rpy="0.0 0.0 0.0" xyz="0.0 0.0 0.0"/>
      <mass value="0.05"/>
      <inertia ixx="7.8" ixy="0.0" ixz="0.0" iyy="7.8" iyz="0.0" izz="7.8"/>
    </inertial>
  </link>
  <link name="gripper_left1">
    <visual>
      <geometry>
        <mesh filename="package://airship_description/urdf/meshes/gripper_left1.stl" scale="0.001 0.001 0.001"/>
      </geometry>
      <origin rpy="0.0 0.0 1.5707963267948966" xyz="0.036 -0.052 0.0"/>
      <material name="dark"/>
    </visual>
    <collision>
      <geometry>
        <mesh filename="package://airship_description/urdf/meshes/gripper_left1.stl" scale="0.001 0.001 0.001"/>
      </geometry>
      <origin rpy="0.0 0.0 1.5707963267948966" xyz="0.036 -0.052 0.0"/>
    </collision>
    <inertial>
      <origin rpy="0.0 0.0 0.0" xyz="0.0 0.0 0.0"/>
      <mass value="0.05"/>
      <inertia ixx="7.8" ixy="0.0" ixz="0.0" iyy="7.8" iyz="0.0" izz="7.8"/>
    </inertial>
  </link>
  <link name="gripper_left2">
    <visual>
      <geometry>
        <mesh filename="package://airship_description/urdf/meshes/gripper_left2.stl" scale="0.001 0.001 0.001"/>
      </geometry>
      <origin rpy="0.0 0.0 1.5707963267948966" xyz="0.03 0.024 -0.018"/>
      <material name="dark"/>
    </visual>
    <collision>
      <geometry>
        <mesh filename="package://airship_description/urdf/meshes/gripper_left2.stl" scale="0.001 0.001 0.001"/>
      </geometry>
      <origin rpy=" 0.0 0.0 1.5707963267948966" xyz="0.03 0.024 -0.018 "/>
    </collision>
    <inertial>
      <origin rpy="0.0 0.0 0.0" xyz="0.0 0.0 0.0"/>
      <mass value="0.05"/>
      <inertia ixx="7.8" ixy="0.0" ixz="0.0" iyy="7.8" iyz="0.0" izz="7.8"/>
    </inertial>
  </link>
  <link name="gripper_left3">
    <visual>
      <geometry>
        <mesh filename="package://airship_description/urdf/meshes/gripper_left3.stl" scale="0.001 0.001 0.001"/>
      </geometry>
      <origin rpy="0.0 3.141592653589793 -1.5707963267948966" xyz="0.034 0.0 -0.012"/>
      <material name="dark"/>
    </visual>
    <collision>
      <geometry>
        <mesh filename="package://airship_description/urdf/meshes/gripper_left3.stl" scale="0.001 0.001 0.001"/>
      </geometry>
      <origin rpy="0.0 3.141592653589793 -1.5707963267948966" xyz="0.034 0.0 -0.012"/>
    </collision>
    <inertial>
      <origin rpy="0.0 0.0 0.0" xyz="0.0 0.0 0.0"/>
      <mass value="0.05"/>
      <inertia ixx="7.8" ixy="0.0" ixz="0.0" iyy="7.8" iyz="0.0" izz="7.8"/>
    </inertial>
  </link>
  <link name="gripper_right1">
    <visual>
      <geometry>
        <mesh filename="package://airship_description/urdf/meshes/gripper_right1.stl" scale="0.001 0.001 0.001"/>
      </geometry>
      <origin rpy="0.0 0.0 1.5707963267948966" xyz="-0.072 -0.05 0.0 "/>
      <material name="dark"/>
    </visual>
    <collision>
      <geometry>
        <mesh filename="package://airship_description/urdf/meshes/gripper_right1.stl" scale="0.001 0.001 0.001"/>
      </geometry>
      <origin rpy="0.0 0.0 1.5707963267948966" xyz="-0.072 -0.05 0.0"/>
    </collision>
    <inertial>
      <origin rpy="0.0 0.0 0.0" xyz="0.0 0.0 0.0"/>
      <mass value="0.05"/>
      <inertia ixx="7.8" ixy="0.0" ixz="0.0" iyy="7.8" iyz="0.0" izz="7.8"/>
    </inertial>
  </link>
  <link name="gripper_right2">
    <visual>
      <geometry>
        <mesh filename="package://airship_description/urdf/meshes/gripper_right2.stl" scale="0.001 0.001 0.001"/>
      </geometry>
      <origin rpy="0.0 0.0 1.5707963267948966" xyz="-0.066 0.023 -0.018"/>
      <material name="dark"/>
    </visual>
    <collision>
      <geometry>
        <mesh filename="package://airship_description/urdf/meshes/gripper_right2.stl" scale="0.001 0.001 0.001"/>
      </geometry>
      <origin rpy="0.0 0.0 1.5707963267948966" xyz="-0.066 0.023 -0.018"/>
    </collision>
    <inertial>
      <origin rpy="0.0 0.0 0.0" xyz="0.0 0.0 0.0"/>
      <mass value="0.05"/>
      <inertia ixx="7.8" ixy="0.0" ixz="0.0" iyy="7.8" iyz="0.0" izz="7.8"/>
    </inertial>
  </link>
  <link name="gripper_right3">
    <visual>
      <geometry>
        <mesh filename="package://airship_description/urdf/meshes/gripper_right3.stl" scale="0.001 0.001 0.001"/>
      </geometry>
      <origin rpy="0.0 3.141592653589793 -1.5707963267948966" xyz="0.0 0.0 -0.012"/>
      <material name="dark"/>
    </visual>
    <collision>
      <geometry>
        <mesh filename="package://airship_description/urdf/meshes/gripper_right3.stl" scale="0.001 0.001 0.001"/>
      </geometry>
      <origin rpy="0.0 3.141592653589793 -1.5707963267948966" xyz="0.0 0.0 -0.012"/>
    </collision>
    <inertial>
      <origin rpy="0.0 0.0 0.0" xyz="0.0 0.0 0.0"/>
      <mass value="0.05"/>
      <inertia ixx="7.8" ixy="0.0" ixz="0.0" iyy="7.8" iyz="0.0" izz="7.8"/>
    </inertial>
  </link>
  <joint name="camera_support_to_gripper_base_joint" type="fixed">
    <origin rpy="0.0 0.0 -1.5707963267948966" xyz="0.0485 -0.002 0.007"/>
    <parent link="camera_support_link"/>
    <child link="gripper_base"/>
  </joint>
  <joint name="gripper_controller" type="revolute">
    <axis xyz="0.0 0.0 1.0"/>
    <limit effort="1000.0" lower="-0.7" upper="0.3" velocity="0.0"/>
    <parent link="gripper_base"/>
    <child link="gripper_left3"/>
    <origin rpy="0.0 0.0 0.0" xyz="-0.018 0.016 0.0"/>
  </joint>
  <joint name="gripper_base_to_gripper_left2" type="revolute">
    <axis xyz="0.0 0.0 1.0"/>
    <limit effort="1000.0" lower="-0.8" upper="0.5" velocity="0.0"/>
    <parent link="gripper_base"/>
    <child link="gripper_left2"/>
    <origin rpy="0.0 0.0 0.0" xyz="-0.05 -0.01 0"/>
    <mimic joint="gripper_controller" multiplier="1.0" offset="0.0"/>
  </joint>
  <joint name="gripper_left3_to_gripper_left1" type="revolute">
    <axis xyz="0.0 0.0 1.0"/>
    <limit effort="1000.0" lower="-0.5" upper="0.5" velocity="0.0"/>
    <parent link="gripper_left3"/>
    <child link="gripper_left1"/>
    <origin rpy="0.0 0.0 0.0" xyz="-0.0356 0.051 -0.018"/>
    <mimic joint="gripper_controller" multiplier="-1.0" offset="0.0"/>
  </joint>
  <joint name="gripper_base_to_gripper_right3" type="revolute">
    <axis xyz="0.0 0.0 1.0"/>
    <limit effort="1000.0" lower="-0.3" upper="0.7" velocity="0"/>
    <parent link="gripper_base"/>
    <child link="gripper_right3"/>
    <origin rpy="0.0 0.0 0.0" xyz="0.018 0.016 0.0"/>
    <mimic joint="gripper_controller" multiplier="-1.0" offset="0.0"/>
  </joint>
  <joint name="gripper_base_to_gripper_right2" type="revolute">
    <axis xyz="0.0 0.0 1.0"/>
    <limit effort="1000.0" lower="-0.5" upper="0.8" velocity="0.0"/>
    <parent link="gripper_base"/>
    <child link="gripper_right2"/>
    <origin rpy="0.0 0.0 0.0" xyz="0.046 -0.01 0.0"/>
    <mimic joint="gripper_controller" multiplier="-1.0" offset="0.0"/>
  </joint>
  <joint name="gripper_right3_to_gripper_right1" type="revolute">
    <axis xyz="0.0 0.0 1.0"/>
    <limit effort="1000.0" lower="-0.5" upper="0.5" velocity="0.0"/>
    <parent link="gripper_right3"/>
    <child link="gripper_right1"/>
    <origin rpy="0.0 0.0 0.0" xyz="0.033 0.051 -0.018"/>
    <mimic joint="gripper_controller" multiplier="1.0" offset="0.0"/>
  </joint>
  <link name="gripper_camera_link">
    <visual>
      <origin rpy="0.0 0.0 0.0" xyz="0.0 0.0 0.0"/>
      <geometry>
        <mesh filename="package://airship_description/urdf/meshes/IntelRealsense_D435.stl" scale="0.001 0.001 0.001"/>
      </geometry>
      <material name="aluminum"/>
    </visual>
  </link>
  <joint name="gripper_camera_joint" type="fixed">
    <parent link="camera_support_link"/>
    <child link="gripper_camera_link"/>
    <origin rpy="0.0 0.0 0.0" xyz="0.042 0 0.048"/>
  </joint>
  <!-- Camera body with origin at bottom screw mount -->
  <joint name="sensor_d435_joint" type="fixed">
    <origin rpy="0 0 0" xyz="0 0 0"/>
    <parent link="gripper_camera_link"/>
    <child link="sensor_d435_bottom_screw_frame"/>
  </joint>
  <link name="sensor_d435_bottom_screw_frame"/>
  <!-- Main camera body -->
  <joint name="sensor_d435_link_joint" type="fixed">
    <origin rpy="0 0 0" xyz="0 0.0175 0.0125"/>
    <parent link="sensor_d435_bottom_screw_frame"/>
    <child link="sensor_d435_link"/>
  </joint>
  <link name="sensor_d435_link">
    <inertial>
      <mass value="0.0564"/>
      <origin xyz="0 0 0"/>
      <inertia ixx="0.003881243" ixy="0.0" ixz="0.0" iyy="0.000498940" iyz="0.0" izz="0.003879257"/>
    </inertial>
  </link>
  <!-- Depth joint and links -->
  <joint name="sensor_d435_depth_joint" type="fixed">
    <origin rpy="0 0 0" xyz="0 0 0"/>
    <parent link="sensor_d435_link"/>
    <child link="sensor_d435_depth_frame"/>
  </joint>
  <link name="sensor_d435_depth_frame"/>
  <joint name="sensor_d435_depth_optical_joint" type="fixed">
    <origin rpy="-1.5707963267948966 0 -1.5707963267948966" xyz="0 0 0"/>
    <parent link="sensor_d435_depth_frame"/>
    <child link="sensor_d435_depth_optical_frame"/>
  </joint>
  <link name="sensor_d435_depth_optical_frame"/>
  <!-- Left IR joint and links -->
  <joint name="sensor_d435_left_ir_joint" type="fixed">
    <origin rpy="0 0 0" xyz="0 0.0 0"/>
    <parent link="sensor_d435_depth_frame"/>
    <child link="sensor_d435_left_ir_frame"/>
  </joint>
  <link name="sensor_d435_left_ir_frame"/>
  <joint name="sensor_d435_left_ir_optical_joint" type="fixed">
    <origin rpy="-1.5707963267948966 0 -1.5707963267948966" xyz="0 0 0"/>
    <parent link="sensor_d435_left_ir_frame"/>
    <child link="sensor_d435_left_ir_optical_frame"/>
  </joint>
  <link name="sensor_d435_left_ir_optical_frame"/>
  <!-- Right IR joint and links -->
  <joint name="sensor_d435_right_ir_joint" type="fixed">
    <origin rpy="0 0 0" xyz="0 -0.05 0"/>
    <parent link="sensor_d435_depth_frame"/>
    <child link="sensor_d435_right_ir_frame"/>
  </joint>
  <link name="sensor_d435_right_ir_frame"/>
  <joint name="sensor_d435_right_ir_optical_joint" type="fixed">
    <origin rpy="-1.5707963267948966 0 -1.5707963267948966" xyz="0 0 0"/>
    <parent link="sensor_d435_right_ir_frame"/>
    <child link="sensor_d435_right_ir_optical_frame"/>
  </joint>
  <link name="sensor_d435_right_ir_optical_frame"/>
  <!-- Color joint and links -->
  <joint name="sensor_d435_color_joint" type="fixed">
    <origin rpy="0 0 0" xyz="0 0.015 0"/>
    <parent link="sensor_d435_depth_frame"/>
    <child link="sensor_d435_color_frame"/>
  </joint>
  <link name="sensor_d435_color_frame"/>
  <joint name="sensor_d435_color_optical_joint" type="fixed">
    <origin rpy="-1.5707963267948966 0 -1.5707963267948966" xyz="0 0 0"/>
    <parent link="sensor_d435_color_frame"/>
    <child link="sensor_d435_color_optical_frame"/>
  </joint>
  <link name="sensor_d435_color_optical_frame"/>
</robot>
